Workbook

Sheet Main
A1: System Parameters
A2: Mode name | B2: Telescope | C2: Channels | D2: IWA (L/D) | E2: OAW (L/D) | F2: DM act/side | G2: Pixels across pupil | H2: L/D per Pix | I2: Link Speed (GB) | J2: Link Latency (sec) | K2: Link Latency (sec)
A3: LUVOIR VIS A | B3: {=IF($A$3="","",INDEX('System Specs'!B:B,MATCH($A$3,'System Specs'!$A:$A,0)))} -> LUVOIR A | C3: {=IF($A$3="","",INDEX('System Specs'!C:C,MATCH($A$3,'System Specs'!$A:$A,0)))} -> 5 | D3: {=IF($A$3="","",INDEX('System Specs'!D:D,MATCH($A$3,'System Specs'!$A:$A,0)))} -> 3.5 | E3: {=IF($A$3="","",INDEX('System Specs'!E:E,MATCH($A$3,'System Specs'!$A:$A,0)))} -> 64 | F3: {=IF($A$3="","",INDEX('System Specs'!F:F,MATCH($A$3,'System Specs'!$A:$A,0)))} -> 128 | G3: {=IF($A$3="","",INDEX('System Specs'!G:G,MATCH($A$3,'System Specs'!$A:$A,0)))} -> 400 | H3: 0.5 | I3: 3.125 | J3: 0.001
A6: Derived Parameters | E6: Other Parameters
A7: Dark Hole Area (L/D)^2 | B7: Pixels | C7: M (2 * Nch * Npix) | D7: Actuators (N) | E7: Nprobe | F7: KFF | G7: NEFCGains | H7: NBytes/Float | I7: Pixel Bit-Depth | J7: Jacobian Size (GB) | K7: M Matrix Size (GB)
A8: =ROUND(PI()*(E3^2-D3^2),0) -> 12829 | B8: =A8/H3/H3 -> 51316 | C8: =B8*C3*2 -> 513160 | D8: =ROUND(2*PI()*(F3/2)^2,0) -> 25736 | E8: 7 | F8: 35 | G8: 4 | H8: 8 | I8: 12 | J8: =C8*D8*H8/10^9 -> 105.65349 | K8: =D8*D8*H8/10^9 -> 5.2987336
A10: Adjoint EFC | I10: Interconnect
A11: Adjoint FLOP Formula | E11: NLFBGS | F11: NGrad | G11: NIF | H11: L-BFGS | I11: Bandwidth (GB) | J11: Energy (pJ/bit) | K11: P2P BW Requirement
A12: NLFBGS*(Channels*(14*Pixels*log(Pixels) + 7*Pixels+ 2*NIF*N + N) + N*(4*Ngrad-1))*NEFC | E12: 15 | F12: 10 | G12: =B8/100 -> 513.16 | H12: 15 | I12: =32 -> 32 | J12: 2.6 | K12: =10*100*((8*C8+16*A8)*7+16*D8) -> 30585584000
I13: Degree | J13: Area (mm2/node)
I14: 2 | J14: 1.3
A17: Workload Specs
A18: Kernels | B18: FLOP Formula | C18: FLOP | D18: GFLOP | E18: Mem Formula | F18: Mem Access | G18: Mem Access (GB) | H18: Mem(TB) | I18: Data Transfer(GB) | J18: Notes
A19: Dither Generation | B19: N | C19: =2*D8 -> 51472 | D19: =C19/10^9 -> 5.1472e-05 | E19: N | F19: =D8*H8 -> 205888 | G19: =F19/10^9 -> 0.000205888 | H19: =F19/10^12 -> 2.05888e-07 | I19: =B8*C3*I8/8/10^9 -> 0.00038487 | J19: Estimation based on pairwise probing
A20: Pairwise Probing | B20: 20*NProbe*M | C20: =20*E8*C8 -> 71842400 | D20: =C20/10^9 -> 0.0718424 | E20: NProbe*M | F20: =E8*C8*H8 -> 28736960 | G20: =F20/10^9 -> 0.02873696 | H20: =F20/10^12 -> 2.873696e-05 | I20: =(1+E8*2)*B8*C3*I8/8/10^9 -> 0.00577305 | J20: Requires optimization to only load full Jacobian once
A21: EKF | B21: KFF*M + 2*M*N | C21: =F8*C8+2*C8*D8 -> 26431332120 | D21: =C21/10^9 -> 26.431332 | E21: KFF*M+M*N | F21: =F8*C8*H8+C8*D8*H8 -> 105797170880 | G21: =F21/10^9 -> 105.79717 | H21: =F21/10^12 -> 0.10579717 | I21: 0
A22: KF | B22: (5*Nprobe + KFF)*Pixels*Channels | C22: =(5*E8+F8)*B8*C3 -> 17960600 | D22: =C22/10^9 -> 0.0179606 | E22: (5*Nprobe + KFF)*Pixels*Channels | F22: =(5*E8+F8)*B8*C3*H8 -> 143684800 | G22: =F22/10^9 -> 0.1436848 | H22: =F22/10^12 -> 0.0001436848 | I22: 0
A23: EFC with Precomputed Gain | B23: 2*N*M+ 2*N*N | C23: =2*D8*C8 -> 26413371520 | D23: =C23/10^9 -> 26.413372 | E23: N(N+M) | F23: =(D8*(C8+D8)*H8) -> 110952219648 | G23: =F23/10^9 -> 110.95222 | H23: =F23/10^12 -> 0.11095222 | I23: =D8*H8/10^9 -> 0.000205888 | J23: =I23*1000*1000 -> 205.888
A24: Jacobian Multiplication | B24: M*N^2 | C24: =C8*D8*D8 -> 339887264719360 | D24: =C24/10^9 -> 339887.26 | E24: MN+2N^2 | F24: =D8*(2*D8+C8) -> 14531369152 | G24: =F24/10^9 -> 14.531369 | H24: =F24/10^12 -> 0.014531369 | I24: 0
A25: Inverse J^TJ | B25: (2*N^3/3)*NEFCGains | C25: =(2*D8^3/3)*G8 -> 45456069035349 | D25: =C25/10^9 -> 45456.069 | E25: 3*N^2*NEFCGains | F25: =3*D8^2*G8*H8 -> 63584802816 | G25: =F25/10^9 -> 63.584803 | H25: =F25/10^12 -> 0.063584803 | I25: 0
A26: Compute Gain | B26: Sum of R24-25 | C26: =C24+C25 -> 385343333754709 | D26: =C26/10^9 -> 385343.33 | F26: =F24+F25 -> 78116171968 | G26: =F26/10^9 -> 78.116172 | H26: =F26/10^12 -> 0.078116172 | I26: 0
A27: Adjoint Based | B27: NLFBGS*(Channels*(14*Pixels*log(Pixels) + 7*Pixels+ 2*NIF*N + N) + N*(4*Ngrad+1))*Nact | C27: =H12*(C3*(14*B8*LOG(B8,2)+7*B8+2*G12*D8+D8)+(4*F12-1)*D8*G8*10) -> 3455191414 | D27: =C27/10^9 -> 3.4551914 | E27: (12*channel + 16)*Nprop^2 | F27: =(12*C3 + 16)*2048*2048 -> 318767104 | G27: =F27/10^9 -> 0.3187671 | H27: =F27/10^12 -> 0.0003187671 | I27: 0
H28: =F30/10^12 -> 0.29229984 | I28: 0
A29: ResNet18 | C29: 2000000000 | D29: =C29/10^9 -> 2 | F29: 500000000 | G29: =F29/10^9 -> 0.5 | H29: =F29/10^12 -> 0.0005 | I29: 0
A30: Modal Kalman Gain | B30: 2/3m^3 +2n^2m | C30: =2/3*(C8)^3+2*(B8)^2*(C8) -> 9.27907e+16 | D30: =C30/10^9 -> 92790680 | E30: (n^2+nm+m^2) | F30: =(B8)^2+(B8)*(C8)+(C8)^2 -> 292299836016 | G30: =F30/10^9 -> 292.29984 | H30: =F30/10^12 -> 0.29229984
A31: Modal status update | B31: n*m | C31: =(B8)*(C8) -> 26333318560 | D31: =C31/10^9 -> 26.333319 | E31: n(n+m) | F31: =(B8)*((B8)+(C8)) -> 28966650416 | G31: =F31/10^9 -> 28.96665 | H31: =F31/10^12 -> 0.02896665
A33: Parallel E distribution | E33: M | F33: =C8*H8 -> 4105280 | G33: =F33/10^9 -> 0.00410528 | H33: =F33/10^12 -> 4.10528e-06
A34: Parallel Vector Collection | E34: N | F34: =D8*H8 -> 205888 | G34: =F34/10^9 -> 0.000205888 | H34: =F34/10^12 -> 2.05888e-07
U35: Formulae
U36: PWP: | V36: GFLOPS | W36: Mem
V37: 20*NProbe*M | W37: NProbe*M
U38: Kalman gain | V38: GFLOPS | W38: Mem
A39: Multiplier | V39: 2/3m^3 +2n^2m | W39: (n2+nm+m2)
A40: 1 | K40: formulae: | U40: Status update | V40: GFLOPS | W40: Mem
A41: Compute System | K41: GFLOP | L41: NLFBGS*(Channels*(14*Pixels*log(Pixels) + 7*Pixels+ 2*NIF*N + N) + N*(4*Ngrad+1))*Nact | V41: n*m | W41: n(n+m)
A42: EFC Compute System | B42: FP32 TFLOP/s | C42: FP64 TFLOP/s | D42: Power (W) | E42: Mem Capacity (GB) | F42: Bandwidth (TB/s) | G42: Scale-up | H42: Weight (kg) | K42: Mem | L42: (12*channel + 16)*Nprop^2
A43: SRAM Solution | B43: {=IF($A$43="","",INDEX('Compute Specs'!B:B,MATCH($A$43,'Compute Specs'!$A:$A,0)))*A40} -> 0 | C43: {=IF($A$43="","",INDEX('Compute Specs'!C:C,MATCH($A$43,'Compute Specs'!$A:$A,0)))*A40} -> 7.5119235 | D43: {=IF($A$43="","",INDEX('Compute Specs'!D:D,MATCH($A$43,'Compute Specs'!$A:$A,0)))*A40} -> 0 | E43: {=IF($A$43="","",INDEX('Compute Specs'!E:E,MATCH($A$43,'Compute Specs'!$A:$A,0)))*A40} -> 110 | F43: {=IF($A$43="","",INDEX('Compute Specs'!F:F,MATCH($A$43,'Compute Specs'!$A:$A,0)))*A40} -> 29.25 | G43: {=IF($A$43="","",INDEX('Compute Specs'!G:G,MATCH($A$43,'Compute Specs'!$A:$A,0)))} | H43: {=IF($A$43="","",INDEX('Compute Specs'!H:H,MATCH($A$43,'Compute Specs'!$A:$A,0)))}
K44: Adjoint | U44: Modal EKF
A45: GP Compute System | B45: FP32 TFLOP/s | C45: FP64 TFLOP/s | D45: Power (W) | E45: Mem Capacity (GB) | F45: Bandwidth (TB/s) | G45: Scale-up | H45: Weight (kg) | K45: Adjoint EFC | L45: Workload Analysis | U45: Precomputed Gain | V45: Workload Analysis
A46: ARM Teledyne LX2160A - Space | B46: {=IF($A$46="","",INDEX('Compute Specs'!B:B,MATCH($A$46,'Compute Specs'!$A:$A,0)))*$A$40} -> 0.0352 | C46: {=IF($A46="","",INDEX('Compute Specs'!C:C,MATCH($A46,'Compute Specs'!$A:$A,0)))*$A$40} -> 0.0352 | D46: {=IF($A46="","",INDEX('Compute Specs'!D:D,MATCH($A46,'Compute Specs'!$A:$A,0)))*A$40} -> 0 | E46: {=IF($A$46="","",INDEX('Compute Specs'!E:E,MATCH($A$46,'Compute Specs'!$A:$A,0)))*A$40} -> 128 | F46: {=IF($A$46="","",INDEX('Compute Specs'!F:F,MATCH($A$46,'Compute Specs'!$A:$A,0)))*A40} -> 0.0576 | G46: {=IF($A$43="","",INDEX('Compute Specs'!G:G,MATCH($A$43,'Compute Specs'!$A:$A,0)))} | H46: {=IF($A$43="","",INDEX('Compute Specs'!H:H,MATCH($A$43,'Compute Specs'!$A:$A,0)))} | K46: Pairwise Probing | L46: GFLOP | M46: Mem(TB) | N46: AI(FLOP/byte) | O46: Roofline Throughput (GB) | P46: Transfer Time | Q46: Bounding Factor | R46: Latency (sec) | S46: Energy (J) | U46: Pairwise Probing | V46: GFLOP | W46: Mem(TB) | X46: AI(FLOP/byte) | Y46: Roofline Throughput (GB) | Z46: Transfer Time | AA46: Bounding Factor | AB46: Latency (sec) | AC46: Energy (J)
...

Sheet Compute Specs
A1: Hardware Analysis | B1: FP32 TFLOP/s | C1: FP64 TFLOP/s | D1: Power (W) | E1: Mem Capacity (GB) | F1: Bandwidth (TB) | G1: Scale-up | H1: Weight (kg) | I1: Sources | J1: Notes | K1: LUVOIR VIS A 10ms 20GB
A2: BAE RAD5545 Optimistic | B2: 0.0037 | C2: 0.0037 | D2: 35 | E2: 4 | F2: 0.006375 | G2: I/O at 40Gb/s | H2: 31.75 | I2: [1], [2], [3] | J2: [2] Mentions "3.7 giga-floating-point operations per second" and "Memory bandwidth of up to 51 Gb/s", Assuming FP is FP64, Assuming GB is not GiB. Divide 51Gb/s by 8 gives 6.375GB/s. [3] Mentions a 31.75kg system but it is for SpaceVPX-SDR, which includes the full payload. | K2: 0.0156
A3: BAE RAD5545 Pessimistic | B3: 0.0037 | C3: 0.0037 | D3: 35 | E3: 4 | F3: 0.0006375 | G3: I/O at 40Gb/s | H3: 31.75 | I3: [1], [2], [3] | J3: Assuming Disk access bandwidth 10x worse than Bandwdith
A4: Apple M3 MAX (30 Core-GPU) | B4: 7.6 | C4: 0 | D4: 78 | E4: 36 | F4: 0.26 | G4: N/A | H4: 1.62 | I4: [4] | J4: Personal Profiling with [4] on MacBook Pro 14'. For reference only. FP64 is not supported by MPS.
A5: Nvidia H100 SXM | B5: 67 | C5: 67 | D5: 700 | E5: 80 | F5: 3.35 | G5: 8 cards at 900GB/s? | H5: 2 | I5: [6] | J5: [6] Mentions FP32/FP64 and FP64 Tensor Core, choosing FP32 and FP64 Tensor Core. Estimating weight based on [7]. | K5: 52.9673 | L5: 402.30787
A6: Nvidia H100 NVL | B6: 60 | C6: 60 | D6: 400 | E6: 94 | F6: 3.9 | G6: 8 cards at 600GB/s | H6: 2 | I6: [6], [7] | J6: Same as above. [7] Mentions weight of 1200g without brackets, etc. Over-estimating to 2kg.
A7: Nvidia H200 SXM | B7: 67 | C7: 67 | D7: 700 | E7: 141 | F7: 4.8 | G7: 8 cards at 900GB/s? | H7: 2 | I7: [12] | J7: Estimated weight similar to H100. | K7: 72.1018 | L7: 403.57005
A8: Nvidia H200 NVL | B8: 60 | C8: 60 | D8: 600 | E8: 141 | F8: 4.8 | G8: 8 cards at 900GB/s? | H8: 2 | I8: [12] | J8: Same as above.
A9: Nvidia B200 | B9: 75 | C9: 37 | D9: 1000 | E9: 180 | F9: 7.7 | G9: 8 cards with HGX B200 | H9: 2 | I9: [5] | J9: [5] Mentions Individual Blackwell GPU with "180GB HBM3E | 7.7TB/s" and FP32 at 75TFLOPS. | K9: 105.1559
A10: Nvidia B300 | B10: 75 | C10: 1.2 | D10: 1400 | E10: 279 | F10: 8
A11: AMD MI300X | B11: 163.4 | C11: 163.4 | D11: 750 | E11: 192 | F11: 5.3 | G11: 8 cards at 128GB/s? | H11: 6 | I11: [8], [10] | J11: [10] Mentions weight as 6kg, probably inaccurate.
A12: AMD MI355X | B12: 78.6 | C12: 157.3 | D12: 1400 | E12: 288 | F12: 8 | G12: 8 cards at 153.6GB/s | H12: 2 | I12: [13] | J12: [13] FLOPS from HPC Vector Performance.
A13: AMD MI325X System | B13: 1300 | C13: 1300 | D13: 8000 | E13: 2048 | F13: 6 | G13: N/A | H13: 75.3 | I13: [11] | J13: [11] Same as above. Net weight estimated from below.
A14: AMD MI300X System | B14: 1307 | C14: 1307 | D14: =750*8 -> 6000 | E14: 1500 | F14: =F11*8 -> 42.4 | G14: N/A | H14: 75.3 | I14: [9] | J14: [9] Mentions the net weight of the entire server chassis as 75.3kg.
A15: NVIDIA DGX H100 System | B15: =8*B5 -> 536 | C15: =8*C5 -> 536 | D15: 10200 | E15: 640 | F15: =F5*8 -> 26.8 | G15: N/A | H15: 130.45 | I15: [14] | J15: Memory results obtained by multiplying a single H100 by 8. | K15: 228.9891
A16: NVIDIA HGX B200 System | B16: =B9*8 -> 600 | C16: =37*8 -> 296 | D16: 14300 | E16: 1400 | F16: 62 | G16: N/A | H16: 84.5 | I16: [16], [15], [19] | J16: [16] mentions a weight of 84.5kg. [19] Mentions DGXB200 at 14.3kW. | K16: 313.4829
A17: NVIDIA DGX GB200 NVL72 System | B17: 5760 | C17: 2880 | D17: 120000 | E17: =186*72 -> 13392 | F17: 576 | G17: N/A | H17: 1360 | I17: [16], [17], [20] | J17: [17] mentions a system weight of 1.36 metric ton. [20] mentions a projected power of 120kW. | K17: 418.3642
A18: Cerebras WSE | B18: =5000 -> 5000 | C18: 0 | D18: 23000 | E18: 44 | F18: 21000 | G18: N/A | H18: 300 | I18: [18], [19] | J18: [19] mentions the system power. Additionally has 1.2TB of memory off-chip.
A19: Xilinx VIRTEX-5QV | B19: 0.192 | C19: 0.192 | D19: 17 | E19: 0.00158 | F19: 0.00675 | G19: N/A | H19: 10 | I19: [21] | J19: [21] Assume 300 Mhz. Bandwidth only using I/O bandwidht
A20: AMD 9950X3D | J20: Self Profiles
A21: Apple M3 MAX (30 Core-GPU) | J21: Self Profiles
A22: RTX 5090 | B22: 66 | C22: 1.7 | E22: 32 | F22: 1.6 | J22: Self Profiles
A23: 2 x EPYC9575F | B23: 9 | C23: =3.3*64*2*32/1000 -> 13.5168 | D23: 800 | E23: 1500 | F23: =0.576*2 -> 1.152 | G23: N/A | J23: Self Profiles
A24: Nvidia Jetson Orin NX | B24: 2.4 | C24: 2.4 | D24: 25 | E24: 16 | F24: 0.102 | J24: 67 AI TOPs. Div by ten
A25: Nvidia AGX Orin | B25: 27.5 | C25: 27.5 | D25: 60 | E25: 64 | F25: 0.2048 | J25: 27.5 AI TOPs. Div by ten
A26: ARM Teledyne LX2160A - Space | B26: =2.2*16/1000 -> 0.0352 | C26: =2.2*16/1000 -> 0.0352 | E26: 128 | F26: 0.0576
A27: SambNoba SN40L
A28: Nvidia B200 x2 | B28: =B9*2 -> 150 | C28: =C9*2 -> 74 | D28: =D9*2 -> 2000 | E28: =E9*2 -> 360 | F28: =F9*2 -> 15.4
A29: Nvidia B200 x4 | B29: =B28*2 -> 300 | C29: =C28*2 -> 148 | D29: =D28*2 -> 4000 | E29: =E28*2 -> 720 | F29: =F28*2 -> 30.8
A30: HBM Solution | C30: 7.5119235 | E30: 110 | F30: 29.25
A31: SRAM Solution | C31: 7.5119235 | E31: 110 | F31: 29.25

Sheet Profile
A1: Kernel | B1: Device | C1: System | D1: Actual Runtime | E1: Predicted Runtime | F1: Accuracy | G1: Notes
A2: Compute Gain | B2: RTX 5090 | C2: HLC | D2: 0.0249 | E2: 0.0453 | F2: =E2/D2 -> 1.8192771
A3: Compute Gain | B3: Apple M3 MAX (30 Core-GPU) | C3: HLC | D3: 0.33027 | E3: 0.3743 | F3: =E3/D3 -> 1.1333152
A4: EFC with Precomputed Gain | B4: RTX 5090 | C4: HLC | D4: 0.0001385 | E4: 0.000147 | F4: =E4/D4 -> 1.0613718
A5: EFC with Precomputed Gain | B5: AMD 9950X3D | C5: HLC | D5: 0.0045294 | E5: 0.00496 | F5: =E5/D5 -> 1.0950678
A6: EFC with Precomputed Gain | B6: Nvidia H100 NVL | C6: LUVOIR VIS A | D6: 0.02769001 | E6: 0.015769177 | F6: =E6/D6 -> 0.56948976
A7: Pairwise Probing | B7: RTX 5090 | C7: LUVOIR VIS A | D7: 0.0004942469 | E7: 8.9803e-06 | F7: =E7/D7 -> 0.018169664
A8: Pairwise Probing | B8: Nvidia H100 NVL | C8: LUVOIR VIS A | D8: 0.0003966924 | E8: 1.2867296e-05 | F8: =E8/D8 -> 0.032436456
A9: ResNet18 | B9: RTX 5090 | C9: HabEx Channel A | D9: 0.00285 | E9: 0.0003125 | F9: =E9/D9 -> 0.10964912 | G9: Batch Size 1
A10: ResNet18 | B10: RTX 5090 | C10: HabEx Channel A | D10: 0.00346 | E10: 0.00088388348 | F10: =E10/D10 -> 0.25545765 | G10: Batch Size 8
A11: ResNet18 | B11: RTX 5090 | C11: HabEx Channel A | D11: 0.00363 | E11: 0.001767767 | F11: =E11/D11 -> 0.48698814 | G11: Batch Size 32
A12: ResNet18 | B12: RTX 5090 | C12: HabEx Channel A | D12: 0.00361 | E12: 0.0025 | F12: =E12/D12 -> 0.69252078 | G12: Batch Size 64
A13: ResNet18 | B13: Nvidia H100 NVL | C13: HabEx Channel A | D13: 0.00124 | E13: 0.00012820513 | F13: =E13/D13 -> 0.10339123 | G13: Batch Size 1
A14: ResNet18 | B14: Nvidia H100 NVL | C14: HabEx Channel A | D14: 0.00122 | E14: 0.00036261886 | F14: =E14/D14 -> 0.29722858 | G14: Batch Size 8
A15: ResNet18 | B15: Nvidia H100 NVL | C15: HabEx Channel A | D15: 0.00143 | E15: 0.0010666667 | F15: =E15/D15 -> 0.74592075 | G15: Batch Size 32
A16: ResNet18 | B16: Nvidia H100 NVL | C16: HabEx Channel A | D16: 0.0018 | E16: 0.0021333333 | F16: =E16/D16 -> 1.1851852 | G16: Batch Size 64
C22: cnn_total_mean=1.24ms backbone_mean=0.96ms head_mean=0.30ms p50=1.21ms p95=1.38ms FPS~808.6
C23: [device=cuda bs=8 amp=False] cnn_total_mean=1.22ms backbone_mean=0.93ms head_mean=0.32ms p50=1.21ms p95=1.28ms FPS~6558.8
C24: [device=cuda bs=32 amp=False] cnn_total_mean=1.43ms backbone_mean=0.99ms head_mean=0.47ms p50=1.43ms p95=1.48ms FPS~22301.8
C25: [device=cuda bs=64 amp=False] cnn_total_mean=1.80ms

Sheet System Specs
A1: Mode name | B1: Telescope | C1: Channels | D1: IWA (L/D) | E1: OAW (L/D) | F1: DM actuators on side | G1: Pixels across pupil
A2: HLC | B2: WFIRST | C2: 7 | D2: 3 | E2: 9 | F2: 48 | G2: 386
A3: HabEx Channel A | B3: HabEx | C3: 5 | D3: 2.4 | E3: 32 | F3: 64 | G3: 400
A4: LUVOIR NUV A | B4: LUVOIR A | C4: 5 | D4: 4 | E4: 40 | F4: 128 | G4: 400
A5: LUVOIR VIS A | B5: LUVOIR A | C5: 5 | D5: 3.5 | E5: 64 | F5: 128 | G5: 400
A6: LUVOIR NIR A | B6: LUVOIR A | C6: 5 | D6: 3.5 | E6: 64 | F6: 128 | G6: 400
A7: LUVOIR NUV B | B7: LUVOIR B | C7: 5 | D7: 4 | E7: 40 | F7: 128 | G7: 400
A8: LUVOIR VIS B | B8: LUVOIR B | C8: 5 | D8: 3.5 | E8: 64 | F8: 128 | G8: 400
A9: LUVOIR NIR B | B9: LUVOIR B | C9: 5 | D9: 3.5 | E9: 64 | F9: 128 | G9: 400
A10: HWO EAC-1 | B10: HWO | F10: 128

Sheet MAC Specs
A1: MAC Design | B1: Tech | C1: Throughput (ops) | D1: Area (um^2) | E1: Power (mW) | F1: Source
A2: DesignWare 500MHz | B2: ASAP 7nm | C2: 0.5 | D2: 1450.9 | E2: 1.4038 | F2: Synthesis
A3: DesignWare 580MHz | B3: ASAP 7nm | C3: =1/1.7 -> 0.58823529 | D3: 1713.5226 | E3: 1.882 | F3: Synthesis
A4: DP-FMA | B4: STM 90nm | C4: 0.71 | D4: 166160 | E4: 39.5 | F4: [26]
A5: DesignWare 330MHz | B5: Nand 45nm | C5: 0.33 | D5: 21043 | E5: 8.52 | F5: Synthesis

Sheet Sources
A1: ID | B1: Type | C1: Title | D1: Link
A2: [1] | B2: Paper | C2: Computational complexities of image plane algorithms for high contrast imaging in space telescopes | D2: https://doi.org/10.1117/1.JATIS.8.4.049003
A3: [2] | B3: Data Sheet | C3: RAD5545™ SpaceVPX | D3: https://www.baesystems.com/en-us/dam/jcr:cd804739-19fa-43f6-b47a-c58eb18e3bba/17-c09-RAD5545-SpaceVPX-SBC-v1-2-Flight-ds-2025-web.pdf
A4: [3] | B4: Data Sheet | C4: SpaceVPX SDR Modular Payload for Space | D4: https://www.baesystems.com/en-us/dam/jcr:76bd3e43-0c31-481e-8e69-ddbf6f29a43d/SpaceVPX_SDR_datasheet_2025_web.pdf
A5: [4] | B5: Codebase | C5: PyTorch GEMM TFLOPS and Memory Bandwidth Benchmark | D5: https://github.com/huoshenlaile/gpu-perf
A6: [5] | B6: Data Sheet | C6: Nvidia Blackwell | D6: https://nvdam.widen.net/s/wwnsxrhm2w/blackwell-datasheet-3384703
A7: [6] | B7: Data Sheet | C7: Nvidia H100 Tensor Core GPU | D7: https://resources.nvidia.com/en-us-hopper-architecture/nvidia-tensor-core-gpu-datasheet?ncid=no-ncid
A8: [7] | B8: Product Brief | C8: Nvidia H100 PCIe GPU | D8: https://www.nvidia.com/content/dam/en-zz/Solutions/gtcs22/data-center/h100/PB-11133-001_v01.pdf
A9: [8] | B9: Data Sheet | C9: AMD Instinc MI300X Accelerator | D9: https://www.amd.com/content/dam/amd/en/documents/instinct-tech-docs/data-sheets/amd-instinct-mi300x-data-sheet.pdf
A10: [9] | B10: Data Sheet | C10: GigaIO Accelerator Pooling Appliance - MI300X | D10: https://gigaio.com/wp-content/uploads/2025/04/GigaIO_Data-Sheet_APA-MI300X_v1.02_04012025.pdf
A11: [10] | B11: Webpage | C11: ANAFRA - AMD Instinct MI300X 192GB HBM3 | D11: https://smicro.eu/amd-instinct-mi300x-192gb-hbm3-100-300000045h?srsltid=AfmBOopYaD0mAzkuXZOuTLlmBbMuVuVBNwtte1N2ylmPc-4rHqllj47L
A12: [11] | B12: Data Sheet | C12: AMD Instinct MI325X Platform | D12: https://www.amd.com/content/dam/amd/en/documents/instinct-tech-docs/product-briefs/instinct-mi325x-platform-datasheet.pdf
... A26: [25] | B26: Repo | C26: convnet-burden | D26: albanie/convnet-burden: Memory consumption and FLOP count estimates for convnets
A27: [26] | B27: Paper | C27: Efficient Multiple-Precision Floating-Point Fused Multiply-Add with Mixed-Precision Support
A28: [27] | B28: Paper | C28: A 22nm 1Mb 1024b-Read and Near-Memory-Computing Dual-Mode STT-MRAM Macro with 42.6GB/s Read Bandwidth for Security-Aware Mobile Devices | D28: https://ieeexplore.ieee.org/document/9063072
A29: [28] | B29: Paper | C29: A 0.5-V 125-MHz 256-Kb 22-nm SRAM With 10-aJ/bit Active Energy and 10-pW/bit Shutdown Power
A30: [29] | B30: Paper | C30: A 38.1Mb/mm^2 SRAM in a 2nm-CMOS-Nanosheet Technology for High-Density and Energy-Efficient Compute
A31: [30] | B31: Paper | C31: A 4-nm 1.15 TB/s HBM3 Interface With Resistor-Tuned Offset Calibration and In Situ Margin Detection
A32: [31] | B32: Paper | C32: A 6.4Gb/s/pin HBM3 Digital PHY with Low-Power, Area-Efficient Techniques for Chiplet-Based AI processors in 12-nm CMOS
A33: [32] | B33: Paper | C33: EMBER: A 100 MHz, 0.86 mm^2 , Multiple-Bits-per-Cell RRAM Macro in 40 nm CMOS with Compact Peripherals and 1.0 pJ/bit Read Circuitry
A34: [33] | B34: Paper | C34: Next-Generation Ultrahigh-Density 3-D Vertical Resistive Switching Memory (VRSM)—Part II: Design Guidelines for Device, Array, and Architecture
A35: [34] | B35: Paper | C35: A 32Mb RRAM in a 12nm FinFet Technology with a 0.0249μm2 Bit-Cell, a 3.2GB/S Read Throughput, a 10KCycle Write Endurance and a 10-Year Retention at 105°C
A36: [35] | B36: Paper | C36: 3-D Vertical Resistive Switching Random Access Memory (3D-VRRAM) With Multilevel Programming for High-Density, Energy-Efficient In-Memory Computing
A37: [36] | B37: Paper | C37: 16-layer 3D Vertical RRAM with Low Read Latency (18ns), High Nonlinearity (>5000) and Ultra-low Leakage Current (~pA) Self-Selective Cells
A38: [37] | B38: Webpage | C38: Leadership HPC Performance with 5th Generation AMD EPYC Processors | D38: https://www.amd.com/en/blogs/2025/leadership-hpc-performance-with-5th-generation-amd.html
A39: [38] | B39: Webpage | C39: AMD's Turin: 5th Gen EPYC Launched | D39: https://chipsandcheese.com/p/amds-turin-5th-gen-epyc-launched

Sheet Obsolete Main
A1: System Parameters
A2: Mode name | B2: Telescope | C2: Channels | D2: IWA (L/D) | E2: OAW (L/D) | F2: DM act/side | G2: Pixels across pupil | H2: L/D per Pix | I2: Link Speed (GB) | J2: Link Latency (sec)
A3: LUVOIR VIS A | B3: {=IF($A$3="","",INDEX('System Specs'!B:B,MATCH($A$3,'System Specs'!$A:$A,0)))} -> LUVOIR A | C3: {=IF($A$3="","",INDEX('System Specs'!C:C,MATCH($A$3,'System Specs'!$A:$A,0)))} -> 5 | D3: {=IF($A$3="","",INDEX('System Specs'!D:D,MATCH($A$3,'System Specs'!$A:$A,0)))} -> 3.5 | E3: {=IF($A$3="","",INDEX('System Specs'!E:E,MATCH($A$3,'System Specs'!$A:$A,0)))} -> 64 | F3: {=IF($A$3="","",INDEX('System Specs'!F:F,MATCH($A$3,'System Specs'!$A:$A,0)))} -> 128 | G3: {=IF($A$3="","",INDEX('System Specs'!G:G,MATCH($A$3,'System Specs'!$A:$A,0)))} -> 400 | H3: 0.5 | I3: 3.125 | J3: 0.001
A6: Derived Parameters | E6: Other Parameters
A7: Dark Hole Area (L/D)^2 | B7: Pixels | C7: M (2 * Nch * Npix) | D7: Actuators (N) | E7: Nprobe | F7: KFF | G7: NEFCGains | H7: NBytes/Float | I7: Pixel Bit-Depth | J7: Jacobian Size (GB)
A8: =ROUND(PI()*(E3^2-D3^2),0) -> 12829 | B8: =A8/H3/H3 -> 51316 | C8: =B8*C3*2 -> 513160 | D8: =ROUND(2*PI()*(F3/2)^2,0) -> 25736 | E8: 7 | F8: 35 | G8: 4 | H8: 8 | I8: 12 | J8: =C8*D8*H8/10^9 -> 105.65349
A10: Adjoint EFC | I10: Interconnect
A11: Adjoint FLOP Formula | E11: NLFBGS | F11: NGrad | G11: NIF | H11: L-BFGS | I11: Bandwidth (GB) | J11: Energy (pJ/bit)
A12: NLFBGS*(Channels*(14*Pixels*log(Pixels) + 7*Pixels+ 2*NIF*N + N) + N*(4*Ngrad-1))*NEFC | E12: 15 | F12: 10 | G12: =B8/100 -> 513.16 | H12: 15 | I12: =32 -> 32 | J12: 2.6
I13: Degree | J13: Area (mm2/node)
I14: 2 | J14: 1.3
A17: Workload Specs
A18: Kernels | B18: FLOP Formula | C18: FLOP | D18: GFLOP | E18: Mem Formula | F18: Mem Access | G18: Mem Access (GB) | H18: Mem(TB) | I18: Data Transfer(GB) | J18: Notes
A19: Dither Generation | B19: N | C19: =2*D8 -> 51472 | D19: =C19/10^9 -> 5.1472e-05 | E19: N | F19: =D8*H8 -> 205888 | G19: =F19/10^9 -> 0.000205888 | H19: =F19/10^12 -> 2.05888e-07 | I19: =B8*C3*I8/8/10^9 -> 0.00038487 | J19: Estimation based on pairwise probing
A20: Pairwise Probing | B20: 20*NProbe*M | C20: =20*E8*C8 -> 71842400 | D20: =C20/10^9 -> 0.0718424 | E20: NProbe*M | F20: =E8*C8*H8 -> 28736960 | G20: =F20/10^9 -> 0.02873696 | H20: =F20/10^12 -> 2.873696e-05 | I20: =(1+E8*2)*B8*C3*I8/8/10^9 -> 0.00577305 | J20: Requires optimization to only load full Jacobian once
A21: EKF | B21: KFF*Pixels*Channel | C21: =F8*B8*C3 -> 8980300 | D21: =C21/10^9 -> 0.0089803 | E21: KFF*Pixels*Channel | F21: =F8*B8*C3*H8 -> 71842400 | G21: =F21/10^9 -> 0.0718424 | H21: =F21/10^12 -> 7.18424e-05 | I21: 0
A22: KF | B22: (5*Nprobe + KFF)*Pixels*Channels | C22: =(5*E8+F8)*B8*C3 -> 17960600 | D22: =C22/10^9 -> 0.0179606 | E22: (5*Nprobe + KFF)*Pixels*Channels | F22: =(5*E8+F8)*B8*C3*H8 -> 143684800 | G22: =F22/10^9 -> 0.1436848 | H22: =F22/10^12 -> 0.0001436848 | I22: 0
A23: EFC with Precomputed Gain | B23: 2*N*M | C23: =2*D8*C8 -> 26413371520 | D23: =C23/10^9 -> 26.413372 | E23: N(N+M) | F23: =(D8*(C8+D8)*H8) -> 110952219648 | G23: =F23/10^9 -> 110.95222 | H23: =F23/10^12 -> 0.11095222 | I23: =D8*H8/10^9 -> 0.000205888 | J23: =I23*1000*1000 -> 205.888
A24: Jacobian Multiplication | B24: M*N^2 | C24: =C8*D8*D8 -> 339887264719360 | D24: =C24/10^9 -> 339887.26 | E24: MN+2N^2 | F24: =D8*(2*D8+C8) -> 14531369152 | G24: =F24/10^9 -> 14.531369 | H24: =F24/10^12 -> 0.014531369 | I24: 0
A25: Inverse J^TJ | B25: (2*N^3/3)*NEFCGains | C25: =(2*D8^3/3)*G8 -> 45456069035349 | D25: =C25/10^9 -> 45456.069 | E25: 3*N^2*NEFCGains | F25: =3*D8^2*G8*H8 -> 63584802816 | G25: =F25/10^9 -> 63.584803 | H25: =F25/10^12 -> 0.063584803 | I25: 0
A26: Compute Gain | C26: =C24+C25 -> 385343333754709 | D26: =C26/10^9 -> 385343.33 | F26: =F24+F25 -> 78116171968 | G26: =F26/10^9 -> 78.116172 | H26: =F26/10^12 -> 0.078116172 | I26: 0
A27: Adjoint Based | B27: NLFBGS*(Channels*(14*Pixels*log(Pixels) + 7*Pixels+ 2*NIF*N + N) + N*(4*Ngrad+1))*Nact | C27: =H12*(C3*(14*B8*LOG(B8,2)+7*B8+2*G12*D8+D8)+(4*F12-1)*D8*G8*10) -> 3455191414 | D27: =C27/10^9 -> 3.4551914 | E27: (12*channel + 16)*Nprop^2 | F27: =(12*C3 + 16)*2048*2048 -> 318767104 | G27: =F27/10^9 -> 0.3187671 | H27: =F27/10^12 -> 0.0003187671 | I27: 0
H28: =F30/10^12 -> 0.29229984 | I28: 0
A29: ResNet18 | C29: 2000000000 | D29: =C29/10^9 -> 2 | F29: 500000000 | G29: =F29/10^9 -> 0.5 | H29: =F29/10^12 -> 0.0005 | I29: 0
A30: Modal Kalman Gain | B30: 2/3m^3 +2n^2m | C30: =2/3*(C8)^3+2*(B8)^2*(C8) -> 9.27907e+16 | D30: =C30/10^9 -> 92790680 | E30: (n^2+nm+m^2) | F30: =(B8)^2+(B8)*(C8)+(C8)^2 -> 292299836016 | G30: =F30/10^9 -> 292.29984 | H30: =F30/10^12 -> 0.29229984
A31: Modal status update | B31: n*m | C31: =(B8)*(C8) -> 26333318560 | D31: =C31/10^9 -> 26.333319 | E31: n(n+m) | F31: =(B8)*((B8)+(C8)) -> 28966650416 | G31: =F31/10^9 -> 28.96665 | H31: =F31/10^12 -> 0.02896665
A33: Parallel E distribution | E33: M | F33: =C8*H8 -> 4105280 | G33: =F33/10^9 -> 0.00410528 | H33: =F33/10^12 -> 4.10528e-06
A34: Parallel Vector Collection | E34: N | F34: =D8*H8 -> 205888 | G34: =F34/10^9 -> 0.000205888 | H34: =F34/10^12 -> 2.05888e-07
U35: Formulae
U36: PWP: | V36: GFLOPS | W36: Mem
V37: 20*NProbe*M | W37: NProbe*M
U38: Kalman gain | V38: GFLOPS | W38: Mem
A39: Multiplier | V39: 2/3m^3 +2n^2m | W39: (n2+nm+m2)
A40: 1 | E40: =B8*C3*I8/8/1000^3/3.125 -> 0.0001231584 | K40: formulae: | U40: Status update | V40: GFLOPS | W40: Mem
A41: Compute System | K41: GFLOP | L41: NLFBGS*(Channels*(14*Pixels*log(Pixels) + 7*Pixels+ 2*NIF*N + N) + N*(4*Ngrad+1))*Nact | V41: n*m | W41: n(n+m)
A42: EFC Compute System | B42: FP32 TFLOP/s | C42: FP64 TFLOP/s | D42: Power (W) | E42: Mem Capacity (GB) | F42: Bandwidth (TB/s) | G42: Scale-up | H42: Weight (kg) | K42: Mem | L42: (12*channel + 16)*Nprop^2
A43: HBM Solution | B43: {=IF($A$43="","",INDEX('Compute Specs'!B:B,MATCH($A$43,'Compute Specs'!$A:$A,0)))*A40} -> 0 | C43: {=IF($A$43="","",INDEX('Compute Specs'!C:C,MATCH($A$43,'Compute Specs'!$A:$A,0)))*A40} -> 7.5119235 | D43: {=IF($A$43="","",INDEX('Compute Specs'!D:D,MATCH($A$43,'Compute Specs'!$A:$A,0)))*A40} -> 0 | E43: {=IF($A$43="","",INDEX('Compute Specs'!E:E,MATCH($A$43,'Compute Specs'!$A:$A,0)))*A40} -> 110 | F43: {=IF($A$43="","",INDEX('Compute Specs'!F:F,MATCH($A$43,'Compute Specs'!$A:$A,0)))*A40} -> 29.25 | G43: {=IF($A$43="","",INDEX('Compute Specs'!G:G,MATCH($A$43,'Compute Specs'!$A:$A,0)))} | H43: {=IF($A$43="","",INDEX('Compute Specs'!H:H,MATCH($A$43,'Compute Specs'!$A:$A,0)))}
K44: Adjoint | U44: Modal EKF
A45: GP Compute System | B45: FP32 TFLOP/s | C45: FP64 TFLOP/s | D45: Power (W) | E45: Mem Capacity (GB) | F45: Bandwidth (TB/s) | G45: Scale-up | H45: Weight (kg) | K45: Adjoint EFC | L45: Workload Analysis | U45: Precomputed Gain | V45: Workload Analysis
A46: ARM Teledyne LX2160A - Space | B46: {=IF($A$46="","",INDEX('Compute Specs'!B:B,MATCH($A$46,'Compute Specs'!$A:$A,0)))*$A$40} -> 0.0352 | C46: {=IF($A46="","",INDEX('Compute Specs'!C:C,MATCH($A46,'Compute Specs'!$A:$A,0)))*$A$40} -> 0.0352 | D46: {=IF($A46="","",INDEX('Compute Specs'!D:D,MATCH($A46,'Compute Specs'!$A:$A,0)))*A$40} -> 0 | E46: {=IF($A$46="","",INDEX('Compute Specs'!E:E,MATCH($A$46,'Compute Specs'!$A:$A,0)))*A$40} -> 128 | F46: {=IF($A$46="","",INDEX('Compute Specs'!F:F,MATCH($A$46,'Compute Specs'!$A:$A,0)))*A40} -> 0.0576 | G46: {=IF($A$43="","",INDEX('Compute Specs'!G:G,MATCH($A$43,'Compute Specs'!$A:$A,0)))} | H46: {=IF($A$43="","",INDEX('Compute Specs'!H:H,MATCH($A$43,'Compute Specs'!$A:$A,0)))} | K46: Pairwise Probing | L46: GFLOP | M46: Mem(TB) | N46: AI(FLOP/byte) | O46: Roofline Throughput (GB) | P46: Transfer Time | Q46: Bounding Factor | R46: Latency (sec) | S46: Energy (J) | U46: Pairwise Probing | V46: GFLOP | W46: Mem(TB) | X46: AI(FLOP/byte) | Y46: Roofline Throughput (GB) | Z46: Transfer Time | AA46: Bounding Factor | AB46: Latency (sec) | AC46: Energy (J)
...

Sheet Transceiver Data
A1: Modulation Scheme | B1: Throughput | C1: Latency | D1: Source
A2: G975.1-I.3 concatenated BCH decoder | B2: 81.9 Gbps | C2: 25.5μs | D2: [22]
A3: End-to-end 1 hop | B3: 10 Gbps | C3: 5.87ms

Sheet Transfer Model
A4: Distance (m) | B4: Distance log(m) | C4: Latency (ms) | D4: SNR | E4: Bandwidth (GB/s) | F4: Transfer Time (ms)
A5: 0 | B5: 0 | C5: =A5/3/10^8*1000 -> 0 | D5: 10000 | E5: 200 | F5: =1/E5 -> 0.005 | G5: 0
A6: 1 | B6: =LOG(A6,10) -> 0 | C6: =A6/3/10^8*1000 -> 3.3333333e-06 | D6: 5000 | E6: =E5/POWER($E$5/$E$15,1/9) -> 85.950595 | F6: =1/E6 -> 0.011634591 | G6: =log(A6) -> 0
A7: 10 | B7: =LOG(A7,10) -> 1 | C7: =A7/3/10^8*1000 -> 3.3333333e-05 | D7: =$D$5/(A7)^2 -> 100 | E7: =E6/POWER($E$5/$E$15,1/9) -> 36.937523 | F7: =1/E7 -> 0.027072741 | G7: =log(A7) -> 1
A8: 100 | B8: =LOG(A8,10) -> 2 | C8: =A8/3/10^8*1000 -> 0.00033333333 | D8: =$D$5/(A8)^2 -> 1 | E8: =E7/POWER($E$5/$E$15,1/9) -> 15.874011 | F8: =1/E8 -> 0.062996052 | G8: =log(A8) -> 2
A9: 1000 | B9: =LOG(A9,10) -> 3 | C9: =A9/3/10^8*1000 -> 0.0033333333 | D9: =$D$5/(A9)^2 -> 0.01 | E9: =E8/POWER($E$5/$E$15,1/9) -> 6.8219032 | F9: =1/E9 -> 0.14658666 | G9: =log(A9) -> 3
A10: 10000 | B10: =LOG(A10,10) -> 4 | C10: =A10/3/10^8*1000 -> 0.033333333 | D10: =$D$5/(A10)^2 -> 0.0001 | E10: =E9/POWER($E$5/$E$15,1/9) -> 2.9317332 | F10: =1/E10 -> 0.34109516 | G10: =log(A10) -> 4
A11: 100000 | B11: =LOG(A11,10) -> 5 | C11: =A11/3/10^8*1000 -> 0.33333333 | D11: =$D$5/(A11)^2 -> 1e-06 | E11: =E10/POWER($E$5/$E$15,1/9) -> 1.259921 | F11: =1/E11 -> 0.79370053 | G11: =log(A11) -> 5
A12: 1000000 | B12: =LOG(A12,10) -> 6 | C12: =A12/3/10^8*1000 -> 3.3333333 | D12: =$D$5/(A12)^2 -> 1e-08 | E12: =E11/POWER($E$5/$E$15,1/9) -> 0.54145482 | F12: =1/E12 -> 1.8468762 | G12: =log(A12) -> 6
A13: 10000000 | B13: =LOG(A13,10) -> 7 | C13: =A13/3/10^8*1000 -> 33.333333 | D13: =$D$5/(A13)^2 -> 1e-10 | E13: =E12/POWER($E$5/$E$15,1/9) -> 0.23269182 | F13: =1/E13 -> 4.2975297 | G13: =log(A13) -> 7
A14: 100000000 | B14: =LOG(A14,10) -> 8 | C14: =A14/3/10^8*1000 -> 333.33333 | D14: =$D$5/(A14)^2 -> 0 | E14: =E13/POWER($E$5/$E$15,1/9) -> 0.1 | F14: =1/E14 -> 10 | G14: =log(A14) -> 8
A15: 150000000 | B15: =LOG(A15,10) -> 8.1760913 | C15: =A15/3/10^8*1000 -> 500 | D15: =$D$5/(A15)^2 -> 0 | E15: 0.1 | F15: =1/E15 -> 10 | G15: =log(A15) -> 8.1760913
A16: =1500000*1000 -> 1500000000 | B16: =LOG(A16,10) -> 9.1760913 | C16: =A16/3/10^8*1000 -> 5000
A18: 100 | B18: =A18*1000 -> 100000 | C18: =B18/3/10^8*1000 -> 0.33333333
C21: 10 second round trip | D21: 100Hz)
C22: 0.1Hz
C23: =sqrt(1000) -> 31.622777
A26: KM | B26: Transfer Time
A27: 100 | B27: =A27/300000 -> 0.00033333333
A28: 1000 | B28: =A28/300000 -> 0.0033333333

Sheet Obsolete Data
A1: System Specs | B1: Channels | C1: IWA (L/D) | D1: OWA (L/D) | E1: DM Actuator on Side | F1: Pixels Across Pupil | G1: L/D per Pix | H1: Dark Hole Area (L/D)^2 | I1: M | J1: Pixels | K1: Visible Actuators (N) | L1: Nprobe | M1: KFF | N1: NEFCGains | O1: NBytes/Float | P1: NEFC
A2: LUVOIR-A | B2: 5 | C2: 3.5 | D2: 64 | E2: 128 | F2: 400 | G2: 0.5 | H2: =ROUND(PI()*(D2^2-C2^2),0) -> 12829 | I2: =B2*J2*2 -> 513160 | J2: =H2/G2/G2 -> 51316 | K2: =ROUND(2*PI()*(E2/2)^2,0) -> 25736 | L2: 7 | M2: 35 | N2: 4 | O2: 4 | P2: 4
A5: Kernel | B5: FLOP Formula | C5: FLOP | D5: Bandwidth Formula | E5: Bandwidth | F5: Capacity Formula | G5: Capacity | H5: Link Transfer Formula | I5: Link Transfer
A6: Probing | B6: 2*N*M | C6: =2*K2*I2 -> 26413371520 | D6: N/A | E6: 0 | F6: ??? | G6: ???
A7: Estimation (EKF) | B7: KFF*#pixels*#channels | C7: =M2*J2*B2 -> 8980300 | D7: 13*NBytes | E7: =13*O2 -> 52 | F7: N*M*NBytes/Float*NEFCGAINS | G7: =I2*K2*O2*N2 -> 211306972160 | H7: 2*#pixels*#channels*Nprobe | I7: =2*J2*B2*L2 -> 3592120
A8: EFC | B8: 2*N*M | C8: =C6 -> 26413371520 | D8: (M+N+1)N + M | E8: =(I2+K2+1)*K2+I2 -> 13869566352 | F8: N*N*NBytes | G8: =K2*K2*O2 -> 2649366784
B9: =2*K2^3/3*N2 -> 45456069035349 | E9: =E8/2^30 -> 12.91704
A10: Control Hz | B10: 100
B12: Required FLOP/s | C12: (In G/s) | D12: Required Memory Throughput/s | E12: (In GB/s) | F12: Required Link Rate | G12: (In GB/s)
A13: Probing | B13: N/A | D13: N/A
A14: Estimation (EKF) | B14: =C7*B10 -> 898030000 | C14: =B14/10^9 -> 0.89803 | D14: N/A | E14: N/A | F14: =I7*B10 -> 359212000 | G14: =F14/10^9 -> 0.359212
A15: EFC | B15: =C6*100 -> 2641337152000 | C15: =B15/10^9 -> 2641.3372 | D15: =E8*100 -> 1386956635200 | E15: =D15/2^30 -> 1291.704
C18: (In T/s) | E18: (In TB/s)
C19: =C15/1000 -> 2.6413372 | E19: =E15/1024 -> 1.2614297
A22: Hardware Analysis | B22: FP32 TFLOP/s | C22: FP64 TFLOP/s | D22: Power (W) | E22: Mem Capacity (GB) | F22: Bandwidth (TB) | G22: Scale-up | H22: Max Hz (fp32) | I22: Max Hz (fp64) | J22: FP32 Time (hr) | K22: Weight (kg)
A23: BAE RAD5545 | B23: 0.001865 | C23: 0 | D23: 35 | E23: 4 | F23: 51 | G23: N/A | H23: =MIN(B23*10^12/$C$8,F23*10^12/$E$8) -> 0.070608177 | I23: =MIN(C23*10^12/$C$8,F23*10^12/$E$8) -> 0 | J23: =1/H23/3600 -> 0.0039340738
A24: Apple M3 MAX | B24: 7.6 | C24: 0 | D24: 78 | E24: 128 | F24: 0.26 | H24: =MIN(B24*10^12/$C$8,F24*10^12/$E$8) -> 18.74608 | I24: =MIN(C24*10^12/$C$8,F24*10^12/$E$8) -> 0 | J24: =1/H24/3600 -> 1.4817913e-05
A25: Nvidia H100 SXM | B25: 134 | C25: 101 | D25: 700 | E25: 80 | F25: 3.35 | G25: 8 cards at 900GB/s? | H25: =MIN(B25*10^12/$C$8,F25*10^12/$E$8) -> 241.53603 | I25: =MIN(C25*10^12/$C$8,F25*10^12/$E$8) -> 241.53603 | J25: =1/H25/3600 -> 1.150047e-06
A26: AMD MI300X | B26: 163.4 | C26: 163.4 | D26: 750 | E26: 192 | F26: 5.3 | G26: 8 cards at 128GB/s? | H26: =MIN(B26*10^12/$C$8,F26*10^12/$E$8) -> 382.13163 | I26: =MIN(C26*10^12/$C$8,F26*10^12/$E$8) -> 382.13163 | J26: =1/H26/3600 -> 7.2691648e-07
A27: AMD MI355X | B27: 78.6 | C27: 157.3 | D27: 1400 | E27: 288 | F27: 8 | G27: 8 cards at 153.6GB/s | H27: =MIN(B27*10^12/$C$8,F27*10^12/$E$8) -> 576.80246 | I27: =MIN(C27*10^12/$C$8,F27*10^12/$E$8) -> 576.80246 | J27: =1/H27/3600 -> 4.8158216e-07
A28: AMD MI325X System | B28: 1300 | C28: 1300 | D28: 8000 | E28: 2048 | F28: 6 | G28: N/A | H28: =MIN(B28*10^12/$C$8,F28*10^12/$E$8) -> 432.60185 | I28: =MIN(C28*10^12/$C$8,F28*10^12/$E$8) -> 432.60185 | J28: =1/H28/3600 -> 6.4210955e-07
A29: AMD MI300X System | B29: 1307 | C29: 1307 | D29: =750*8 -> 6000 | E29: 1500 | F29: =F26*8 -> 42.4 | G29: N/A | H29: =MIN(B29*10^12/$C$8,F29*10^12/$E$8) -> 3057.053 | I29: =MIN(C29*10^12/$C$8,F29*10^12/$E$8) -> 3057.053 | J29: =1/H29/3600 -> 9.0864559e-08
A30: NVIDIA DGX H100 System | B30: =8*B25 -> 1072 | C30: =8*C25 -> 808 | D30: 10200 | E30: 640 | F30: =F25*8 -> 26.8 | G30: N/A | H30: =MIN(B30*10^12/$C$8,F30*10^12/$E$8) -> 1932.2882 | I30: =MIN(C30*10^12/$C$8,F30*10^12/$E$8) -> 1932.2882 | J30: =1/H30/3600 -> 1.4375587e-07
A31: NVIDIA DGX GB200 NVL72 System | B31: 5760 | C31: 2880 | D31: =1200*72 -> 86400 | E31: =186*72 -> 13392 | F31: 576 | G31: N/A | H31: =MIN(B31*10^12/$C$8,F31*10^12/$E$8) -> 41529.777 | I31: =MIN(C31*10^12/$C$8,F31*10^12/$E$8) -> 41529.777 | J31: =1/H31/3600 -> 6.6886412e-09
A32: Cerebras WSE | B32: =B33/25 -> 5000 | D32: 20000 | E32: 40 | F32: 220000 | H32: =MIN(B32*10^12/$C$8,F32*10^12/$E$8) -> 189298.06 | I32: =MIN(C32*10^12/$C$8,F32*10^12/$E$8) -> 0 | J32: =1/H32/3600 -> 1.4674095e-09 | K32: 300
B33: 125000
A35: FP32 ALU Estimates
A36: Frequency (GHz) | B36: Area (mm^2)
A37: 2 | B37: 0.01
A40: Max Die Size | B40: 744
A41: FP 32 ALU Size (mm^2) | B41: 0.0015
A42: Compute Area | B42: =B40*0.7 -> 520.8
A43: Total PE | B43: =B42/B41 -> 347200
A44: Systolic Array Size | B44: =FLOOR(SQRT(B43),1) -> 589
A45: Frequency (MHz) | B45: 2500
A46: MAC Flops (TFLOP/s) | B46: =B43*B45/1000/1000 -> 868
A48: Hz | B48: 100
A49: MAC Flops (TFLOP/s) | B49: =B48*C8 -> 2641337152000
A50: Frequency (MHz) | B50: 2500
A51: FLOP/Cycle | B51: =B49/B50/10^6 -> 1056.5349
...
